Workbook

Sheet solutions
A1: تمرین | B1: پرسش | C1: فرمول | D1: جواب | E1: جواب مورد انتظار
A2: ع۱ | B2: تعداد سطر | C2: COUNTA(raw!B2:B43) | D2: =COUNTA(raw!B2:B43) | E2: 42
A3: ع۱ | B3: pid یکتا | C3: SUMPRODUCT(1/COUNTIF(raw!B2:B43,raw!B2:B43)) | D3: =SUMPRODUCT(1/COUNTIF(raw!B2:B43,raw!B2:B43)) | E3: 40
A4: ع۱ | B4: تکرار کامل | C4: SUM(raw!N2:N43) | D4: =SUM(raw!N2:N43) | E4: 1
A5: ع۱ | B5: تکرار کلید | C5: SUM(raw!O2:O43) | D5: =SUM(raw!O2:O43) | E5: 1
A6: ع۲ | B6: سطر پس از P1–P2 | C6: SUM(raw!P2:P43) | D6: =SUM(raw!P2:P43) | E6: 40
A7: ع۲ | B7: زن | C7: COUNTIFS(raw!P2:P43,1,raw!Q2:Q43,"F") | D7: =COUNTIFS(raw!P2:P43,1,raw!Q2:Q43,"F") | E7: 14
A8: ع۲ | B8: مرد | C8: COUNTIFS(raw!P2:P43,1,raw!Q2:Q43,"M") | D8: =COUNTIFS(raw!P2:P43,1,raw!Q2:Q43,"M") | E8: 26
A9: ع۲ | B9: yes | C9: COUNTIFS(raw!P2:P43,1,raw!R2:R43,"yes") | D9: =COUNTIFS(raw!P2:P43,1,raw!R2:R43,"yes") | E9: 4
A10: ع۲ | B10: no | C10: COUNTIFS(raw!P2:P43,1,raw!R2:R43,"no") | D10: =COUNTIFS(raw!P2:P43,1,raw!R2:R43,"no") | E10: 35
A11: ع۲ | B11: smoker گمشده | C11: COUNTIFS(raw!P2:P43,1,raw!R2:R43,"") | D11: =COUNTIFS(raw!P2:P43,1,raw!R2:R43,"") | E11: 1
A12: ع۳ | B12: قد به متر | C12: COUNTIFS(raw!P2:P43,1,raw!F2:F43,"<3") | D12: =COUNTIFS(raw!P2:P43,1,raw!F2:F43,"<3") | E12: 1
A13: ع۳ | B13: قد گمشده | C13: COUNTIFS(raw!P2:P43,1,raw!S2:S43,"") | D13: =COUNTIFS(raw!P2:P43,1,raw!S2:S43,"") | E13: 1
A14: ع۳ | B14: وزن گمشده | C14: COUNTIFS(raw!P2:P43,1,raw!T2:T43,"") | D14: =COUNTIFS(raw!P2:P43,1,raw!T2:T43,"") | E14: 1
A15: ع۳ | B15: sbp گمشده (P7) | C15: COUNTIFS(raw!P2:P43,1,raw!U2:U43,"") | D15: =COUNTIFS(raw!P2:P43,1,raw!U2:U43,"") | E15: 2
A16: ع۴ | B16: dbp≥sbp | C16: SUMIFS(raw!W2:W43,raw!P2:P43,1) | D16: =SUMIFS(raw!W2:W43,raw!P2:P43,1) | E16: 1
A17: ع۴ | B17: مرد باردار | C17: COUNTIFS(raw!P2:P43,1,raw!Q2:Q43,"M",raw!K2:K43,"yes") | D17: =COUNTIFS(raw!P2:P43,1,raw!Q2:Q43,"M",raw!K2:K43,"yes") | E17: 1
A18: ع۴ | B18: تولد بعد از ویزیت | C18: SUMPRODUCT((raw!P2:P43=1)*(raw!D2:D43>raw!E2:E43)) | D18: =SUMPRODUCT((raw!P2:P43=1)*(raw!D2:D43>raw!E2:E43)) | E18: 1
A19: ع۴ | B19: زیر ۱۸ | C19: COUNTIFS(raw!P2:P43,1,raw!AB2:AB43,"<18") | D19: =COUNTIFS(raw!P2:P43,1,raw!AB2:AB43,"<18") | E19: 1
A20: ع۴ | B20: n تحلیل | C20: SUM(raw!AC2:AC43) | D20: =SUM(raw!AC2:AC43) | E20: 39
A21: ع۵ | B21: میانگین سن | C21: AVERAGEIFS(raw!AB2:AB43,raw!AC2:AC43,1) | D21: =AVERAGEIFS(raw!AB2:AB43,raw!AC2:AC43,1) | E21: 48.42
A22: ع۵ | B22: n سن | C22: COUNTIFS(raw!AC2:AC43,1,raw!AB2:AB43,">=0") | D22: =COUNTIFS(raw!AC2:AC43,1,raw!AB2:AB43,">=0") | E22: 38
A23: ع۵ | B23: میانگین BMI | C23: AVERAGEIFS(raw!AD2:AD43,raw!AC2:AC43,1) | D23: =AVERAGEIFS(raw!AD2:AD43,raw!AC2:AC43,1) | E23: 26.43
A24: ع۵ | B24: BMI≥30 | C24: COUNTIFS(raw!AC2:AC43,1,raw!AD2:AD43,">=30") | D24: =COUNTIFS(raw!AC2:AC43,1,raw!AD2:AD43,">=30") | E24: 5
A25: ع۵ | B25: گروه ۱ (<40) | C25: COUNTIFS(raw!AC2:AC43,1,raw!AE2:AE43,1) | D25: =COUNTIFS(raw!AC2:AC43,1,raw!AE2:AE43,1) | E25: 14
A26: ع۵ | B26: گروه ۲ (40–59) | C26: COUNTIFS(raw!AC2:AC43,1,raw!AE2:AE43,2) | D26: =COUNTIFS(raw!AC2:AC43,1,raw!AE2:AE43,2) | E26: 14
A27: ع۵ | B27: گروه ۳ (≥60) | C27: COUNTIFS(raw!AC2:AC43,1,raw!AE2:AE43,3) | D27: =COUNTIFS(raw!AC2:AC43,1,raw!AE2:AE43,3) | E27: 10
A28: ع۵ | B28: میانگین sbp | C28: AVERAGEIFS(raw!X2:X43,raw!AC2:AC43,1) | D28: =AVERAGEIFS(raw!X2:X43,raw!AC2:AC43,1) | E28: 143
A29: ع۵ | B29: n sbp | C29: COUNTIFS(raw!AC2:AC43,1,raw!X2:X43,">0") | D29: =COUNTIFS(raw!AC2:AC43,1,raw!X2:X43,">0") | E29: 36
A30: ع۶ | B30: سطر آزمایش | C30: COUNTA(labs!A2:A84) | D30: =COUNTA(labs!A2:A84) | E30: 83
A31: ع۶ | B31: بیمار در آزمایش | C31: SUMPRODUCT(1/COUNTIF(labs!A2:A84,labs!A2:A84)) | D31: =SUMPRODUCT(1/COUNTIF(labs!A2:A84,labs!A2:A84)) | E31: 36
A32: ع۶ | B32: بدون آزمایش | C32: COUNTIFS(raw!AC2:AC43,1,raw!AF2:AF43,0) | D32: =COUNTIFS(raw!AC2:AC43,1,raw!AF2:AF43,0) | E32: 5
A33: ع۶ | B33: میانگین LDL بیماران | C33: AVERAGEIFS(raw!AG2:AG43,raw!AC2:AC43,1) | D33: =AVERAGEIFS(raw!AG2:AG43,raw!AC2:AC43,1) | E33: 120.58
A34: ع۶ | B34: ۱ آزمایش | C34: COUNTIFS(raw!AC2:AC43,1,raw!AF2:AF43,1) | D34: =COUNTIFS(raw!AC2:AC43,1,raw!AF2:AF43,1) | E34: 5
A35: ع۶ | B35: ۲ آزمایش | C35: COUNTIFS(raw!AC2:AC43,1,raw!AF2:AF43,2) | D35: =COUNTIFS(raw!AC2:AC43,1,raw!AF2:AF43,2) | E35: 12
A36: ع۶ | B36: ۳ آزمایش | C36: COUNTIFS(raw!AC2:AC43,1,raw!AF2:AF43,3) | D36: =COUNTIFS(raw!AC2:AC43,1,raw!AF2:AF43,3) | E36: 17
A37: ع۶ | B37: شناسهٔ بی‌جفت (یکتا) | C37: SUMPRODUCT(labs!E2:E84/COUNTIF(labs!A2:A84,labs!A2:A84)) | D37: =SUMPRODUCT(labs!E2:E84/COUNTIF(labs!A2:A84,labs!A2:A84)) | E37: 2
A38: ع۷ | B38: n نهایی | C38: SUM(raw!AC2:AC43)+COUNTA(site2!B2:B6) | D38: =SUM(raw!AC2:AC43)+COUNTA(site2!B2:B6) | E38: 44
A39: ع۷ | B39: میانگین sbp نهایی | C39: (SUMIFS(raw!X2:X43,raw!AC2:AC43,1)+SUM(site2!H2:H6))/(COUNTIFS(raw!AC2:AC43,1,raw!X2:X43,">0")+COUNT(site2!H2:H6)) | D39: =(SUMIFS(raw!X2:X43,raw!AC2:AC43,1)+SUM(site2!H2:H6))/(COUNTIFS(raw!AC2:AC43,1,raw!X2:X43,">0")+COUNT(site2!H2:H6)) | E39: 143
A40: ع۷ | B40: n sbp نهایی | C40: COUNTIFS(raw!AC2:AC43,1,raw!X2:X43,">0")+COUNT(site2!H2:H6) | D40: =COUNTIFS(raw!AC2:AC43,1,raw!X2:X43,">0")+COUNT(site2!H2:H6) | E40: 41

Sheet raw
A1: entry_no | B1: pid | C1: sex | D1: dob | E1: visit_date | F1: height_cm | G1: weight_kg | H1: sbp | I1: dbp | J1: smoker | K1: pregnant | L1: hba1c | M1: key | N1: exact_dup | O1: key_dup | P1: keep | Q1: sex_c | R1: smoker_c | S1: height_c | T1: weight_c | U1: sbp_1 | V1: dbp_1 | W1: bp_incons | X1: sbp_c | Y1: dbp_c | Z1: preg_c | AA1: dob_c | AB1: age | AC1: in_analysis | AD1: bmi | AE1: age_group | AF1: n_tests | AG1: mean_ldl
A2: 1 | B2: 1 | C2: M | D2: 32294 | E2: 45674 | F2: 166 | G2: 59 | H2: 156 | I2: 88 | J2: no | K2: yes | L2: 6.5 | M2: =A2&"|"&B2&"|"&C2&"|"&D2&"|"&E2&"|"&F2&"|"&G2&"|"&H2&"|"&I2&"|"&J2&"|"&K2&"|"&L2 | N2: =IF(COUNTIF(M$2:M2,M2)>1,1,0) | O2: =IF(AND(N2=0,COUNTIFS(B$2:B$43,B2,N$2:N$43,0,A$2:A$43,"<"&A2)>0),1,0) | P2: =IF(N2+O2=0,1,0) | Q2: =UPPER(LEFT(TRIM(C2),1)) | R2: =IF(UPPER(LEFT(TRIM(J2),1))="Y","yes",IF(UPPER(LEFT(TRIM(J2),1))="N","no","")) | S2: =IF(F2<3,F2*100,IF(OR(F2<120,F2>220),"",F2)) | T2: =IF(OR(G2<30,G2>250),"",G2) | U2: =IF(OR(H2=-99,H2<70,H2>260),"",H2) | V2: =IF(OR(I2<40,I2>150),"",I2) | W2: =IF(AND(U2<>"",V2<>""),IF(V2>=U2,1,0),0) | X2: =IF(W2=1,"",U2) | Y2: =IF(W2=1,"",V2) | Z2: =IF(Q2="M","",K2) | AA2: =IF(D2>E2,"",D2) | AB2: =IF(AA2="","",DATEDIF(AA2,E2,"y")) | AC2: =IF(AND(P2=1,OR(AB2="",AB2>=18)),1,0) | AD2: =IF(OR(S2="",T2=""),"",T2/(S2/100)^2) | AE2: =IF(AB2="","",IF(AB2<40,1,IF(AB2<60,2,3))) | AF2: =COUNTIF(labs!$A$2:$A$84,B2) | AG2: =IF(AF2=0,"",AVERAGEIF(labs!$A$2:$A$84,B2,labs!$C$2:$C$84))
A3: 2 | B3: 2 | C3: m | D3: 24529 | E3: 45742 | F3: 182 | G3: 85.2 | H3: 154 | I3: 87 | J3: no | L3: 5.9 | M3: =A3&"|"&B3&"|"&C3&"|"&D3&"|"&E3&"|"&F3&"|"&G3&"|"&H3&"|"&I3&"|"&J3&"|"&K3&"|"&L3 | N3: =IF(COUNTIF(M$2:M3,M3)>1,1,0) | O3: =IF(AND(N3=0,COUNTIFS(B$2:B$43,B3,N$2:N$43,0,A$2:A$43,"<"&A3)>0),1,0) | P3: =IF(N3+O3=0,1,0) | Q3: =UPPER(LEFT(TRIM(C3),1)) | R3: =IF(UPPER(LEFT(TRIM(J3),1))="Y","yes",IF(UPPER(LEFT(TRIM(J3),1))="N","no","")) | S3: =IF(F3<3,F3*100,IF(OR(F3<120,F3>220),"",F3)) | T3: =IF(OR(G3<30,G3>250),"",G3) | U3: =IF(OR(H3=-99,H3<70,H3>260),"",H3) | V3: =IF(OR(I3<40,I3>150),"",I3) | W3: =IF(AND(U3<>"",V3<>""),IF(V3>=U3,1,0),0) | X3: =IF(W3=1,"",U3) | Y3: =IF(W3=1,"",V3) | Z3: =IF(Q3="M","",K3) | AA3: =IF(D3>E3,"",D3) | AB3: =IF(AA3="","",DATEDIF(AA3,E3,"y")) | AC3: =IF(AND(P3=1,OR(AB3="",AB3>=18)),1,0) | AD3: =IF(OR(S3="",T3=""),"",T3/(S3/100)^2) | AE3: =IF(AB3="","",IF(AB3<40,1,IF(AB3<60,2,3))) | AF3: =COUNTIF(labs!$A$2:$A$84,B3) | AG3: =IF(AF3=0,"",AVERAGEIF(labs!$A$2:$A$84,B3,labs!$C$2:$C$84))
A4: 3 | B4: 3 | C4: F | D4: 39498 | E4: 45708 | F4: 153 | G4: 62.2 | H4: 145 | I4: 92 | J4: no | K4: no | L4: 7.6 | M4: =A4&"|"&B4&"|"&C4&"|"&D4&"|"&E4&"|"&F4&"|"&G4&"|"&H4&"|"&I4&"|"&J4&"|"&K4&"|"&L4 | N4: =IF(COUNTIF(M$2:M4,M4)>1,1,0) | O4: =IF(AND(N4=0,COUNTIFS(B$2:B$43,B4,N$2:N$43,0,A$2:A$43,"<"&A4)>0),1,0) | P4: =IF(N4+O4=0,1,0) | Q4: =UPPER(LEFT(TRIM(C4),1)) | R4: =IF(UPPER(LEFT(TRIM(J4),1))="Y","yes",IF(UPPER(LEFT(TRIM(J4),1))="N","no","")) | S4: =IF(F4<3,F4*100,IF(OR(F4<120,F4>220),"",F4)) | T4: =IF(OR(G4<30,G4>250),"",G4) | U4: =IF(OR(H4=-99,H4<70,H4>260),"",H4) | V4: =IF(OR(I4<40,I4>150),"",I4) | W4: =IF(AND(U4<>"",V4<>""),IF(V4>=U4,1,0),0) | X4: =IF(W4=1,"",U4) | Y4: =IF(W4=1,"",V4) | Z4: =IF(Q4="M","",K4) | AA4: =IF(D4>E4,"",D4) | AB4: =IF(AA4="","",DATEDIF(AA4,E4,"y")) | AC4: =IF(AND(P4=1,OR(AB4="",AB4>=18)),1,0) | AD4: =IF(OR(S4="",T4=""),"",T4/(S4/100)^2) | AE4: =IF(AB4="","",IF(AB4<40,1,IF(AB4<60,2,3))) | AF4: =COUNTIF(labs!$A$2:$A$84,B4) | AG4: =IF(AF4=0,"",AVERAGEIF(labs!$A$2:$A$84,B4,labs!$C$2:$C$84))
A5: 4 | B5: 4 | C5: m | D5: 34212 | E5: 45808 | F5: 172 | G5: 76.4 | H5: 152 | I5: 97 | J5: no | L5: 5.8 | M5: =A5&"|"&B5&"|"&C5&"|"&D5&"|"&E5&"|"&F5&"|"&G5&"|"&H5&"|"&I5&"|"&J5&"|"&K5&"|"&L5 | N5: =IF(COUNTIF(M$2:M5,M5)>1,1,0) | O5: =IF(AND(N5=0,COUNTIFS(B$2:B$43,B5,N$2:N$43,0,A$2:A$43,"<"&A5)>0),1,0) | P5: =IF(N5+O5=0,1,0) | Q5: =UPPER(LEFT(TRIM(C5),1)) | R5: =IF(UPPER(LEFT(TRIM(J5),1))="Y","yes",IF(UPPER(LEFT(TRIM(J5),1))="N","no","")) | S5: =IF(F5<3,F5*100,IF(OR(F5<120,F5>220),"",F5)) | T5: =IF(OR(G5<30,G5>250),"",G5) | U5: =IF(OR(H5=-99,H5<70,H5>260),"",H5) | V5: =IF(OR(I5<40,I5>150),"",I5) | W5: =IF(AND(U5<>"",V5<>""),IF(V5>=U5,1,0),0) | X5: =IF(W5=1,"",U5) | Y5: =IF(W5=1,"",V5) | Z5: =IF(Q5="M","",K5) | AA5: =IF(D5>E5,"",D5) | AB5: =IF(AA5="","",DATEDIF(AA5,E5,"y")) | AC5: =IF(AND(P5=1,OR(AB5="",AB5>=18)),1,0) | AD5: =IF(OR(S5="",T5=""),"",T5/(S5/100)^2) | AE5: =IF(AB5="","",IF(AB5<40,1,IF(AB5<60,2,3))) | AF5: =COUNTIF(labs!$A$2:$A$84,B5) | AG5: =IF(AF5=0,"",AVERAGEIF(labs!$A$2:$A$84,B5,labs!$C$2:$C$84))
A6: 5 | B6: 5 | C6: F | D6: 17736 | E6: 45926 | F6: 1.68 | G6: 73.5 | H6: 138 | I6: 80 | J6: no | K6: no | L6: 7.2 | M6: =A6&"|"&B6&"|"&C6&"|"&D6&"|"&E6&"|"&F6&"|"&G6&"|"&H6&"|"&I6&"|"&J6&"|"&K6&"|"&L6 | N6: =IF(COUNTIF(M$2:M6,M6)>1,1,0) | O6: =IF(AND(N6=0,COUNTIFS(B$2:B$43,B6,N$2:N$43,0,A$2:A$43,"<"&A6)>0),1,0) | P6: =IF(N6+O6=0,1,0) | Q6: =UPPER(LEFT(TRIM(C6),1)) | R6: =IF(UPPER(LEFT(TRIM(J6),1))="Y","yes",IF(UPPER(LEFT(TRIM(J6),1))="N","no","")) | S6: =IF(F6<3,F6*100,IF(OR(F6<120,F6>220),"",F6)) | T6: =IF(OR(G6<30,G6>250),"",G6) | U6: =IF(OR(H6=-99,H6<70,H6>260),"",H6) | V6: =IF(OR(I6<40,I6>150),"",I6) | W6: =IF(AND(U6<>"",V6<>""),IF(V6>=U6,1,0),0) | X6: =IF(W6=1,"",U6) | Y6: =IF(W6=1,"",V6) | Z6: =IF(Q6="M","",K6) | AA6: =IF(D6>E6,"",D6) | AB6: =IF(AA6="","",DATEDIF(AA6,E6,"y")) | AC6: =IF(AND(P6=1,OR(AB6="",AB6>=18)),1,0) | AD6: =IF(OR(S6="",T6=""),"",T6/(S6/100)^2) | AE6: =IF(AB6="","",IF(AB6<40,1,IF(AB6<60,2,3))) | AF6: =COUNTIF(labs!$A$2:$A$84,B6) | AG6: =IF(AF6=0,"",AVERAGEIF(labs!$A$2:$A$84,B6,labs!$C$2:$C$84))
A7: 6 | B7: 6 | C7: Male | D7: 20537 | E7: 45861 | F7: 175 | G7: 83.1 | H7: 168 | I7: 101 | J7: no | L7: 6.3 | M7: =A7&"|"&B7&"|"&C7&"|"&D7&"|"&E7&"|"&F7&"|"&G7&"|"&H7&"|"&I7&"|"&J7&"|"&K7&"|"&L7 | N7: =IF(COUNTIF(M$2:M7,M7)>1,1,0) | O7: =IF(AND(N7=0,COUNTIFS(B$2:B$43,B7,N$2:N$43,0,A$2:A$43,"<"&A7)>0),1,0) | P7: =IF(N7+O7=0,1,0) | Q7: =UPPER(LEFT(TRIM(C7),1)) | R7: =IF(UPPER(LEFT(TRIM(J7),1))="Y","yes",IF(UPPER(LEFT(TRIM(J7),1))="N","no","")) | S7: =IF(F7<3,F7*100,IF(OR(F7<120,F7>220),"",F7)) | T7: =IF(OR(G7<30,G7>250),"",G7) | U7: =IF(OR(H7=-99,H7<70,H7>260),"",H7) | V7: =IF(OR(I7<40,I7>150),"",I7) | W7: =IF(AND(U7<>"",V7<>""),IF(V7>=U7,1,0),0) | X7: =IF(W7=1,"",U7) | Y7: =IF(W7=1,"",V7) | Z7: =IF(Q7="M","",K7) | AA7: =IF(D7>E7,"",D7) | AB7: =IF(AA7="","",DATEDIF(AA7,E7,"y")) | AC7: =IF(AND(P7=1,OR(AB7="",AB7>=18)),1,0) | AD7: =IF(OR(S7="",T7=""),"",T7/(S7/100)^2) | AE7: =IF(AB7="","",IF(AB7<40,1,IF(AB7<60,2,3))) | AF7: =COUNTIF(labs!$A$2:$A$84,B7) | AG7: =IF(AF7=0,"",AVERAGEIF(labs!$A$2:$A$84,B7,labs!$C$2:$C$84))
A8: 7 | B8: 7 | C8: male | D8: 20528 | E8: 45946 | F8: 168 | G8: 57.1 | H8: 141 | I8: 87 | J8: no | M8: =A8&"|"&B8&"|"&C8&"|"&D8&"|"&E8&"|"&F8&"|"&G8&"|"&H8&"|"&I8&"|"&J8&"|"&K8&"|"&L8 | N8: =IF(COUNTIF(M$2:M8,M8)>1,1,0) | O8: =IF(AND(N8=0,COUNTIFS(B$2:B$43,B8,N$2:N$43,0,A$2:A$43,"<"&A8)>0),1,0) | P8: =IF(N8+O8=0,1,0) | Q8: =UPPER(LEFT(TRIM(C8),1)) | R8: =IF(UPPER(LEFT(TRIM(J8),1))="Y","yes",IF(UPPER(LEFT(TRIM(J8),1))="N","no","")) | S8: =IF(F8<3,F8*100,IF(OR(F8<120,F8>220),"",F8)) | T8: =IF(OR(G8<30,G8>250),"",G8) | U8: =IF(OR(H8=-99,H8<70,H8>260),"",H8) | V8: =IF(OR(I8<40,I8>150),"",I8) | W8: =IF(AND(U8<>"",V8<>""),IF(V8>=U8,1,0),0) | X8: =IF(W8=1,"",U8) | Y8: =IF(W8=1,"",V8) | Z8: =IF(Q8="M","",K8) | AA8: =IF(D8>E8,"",D8) | AB8: =IF(AA8="","",DATEDIF(AA8,E8,"y")) | AC8: =IF(AND(P8=1,OR(AB8="",AB8>=18)),1,0) | AD8: =IF(OR(S8="",T8=""),"",T8/(S8/100)^2) | AE8: =IF(AB8="","",IF(AB8<40,1,IF(AB8<60,2,3))) | AF8: =COUNTIF(labs!$A$2:$A$84,B8) | AG8: =IF(AF8=0,"",AVERAGEIF(labs!$A$2:$A$84,B8,labs!$C$2:$C$84))
A9: 8 | B9: 8 | C9: Female | D9: 27351 | E9: 45805 | F9: 160 | G9: 42.8 | H9: 150 | I9: 85 | J9: no | K9: no | L9: 9.2 | M9: =A9&"|"&B9&"|"&C9&"|"&D9&"|"&E9&"|"&F9&"|"&G9&"|"&H9&"|"&I9&"|"&J9&"|"&K9&"|"&L9 | N9: =IF(COUNTIF(M$2:M9,M9)>1,1,0) | O9: =IF(AND(N9=0,COUNTIFS(B$2:B$43,B9,N$2:N$43,0,A$2:A$43,"<"&A9)>0),1,0) | P9: =IF(N9+O9=0,1,0) | Q9: =UPPER(LEFT(TRIM(C9),1)) | R9: =IF(UPPER(LEFT(TRIM(J9),1))="Y","yes",IF(UPPER(LEFT(TRIM(J9),1))="N","no","")) | S9: =IF(F9<3,F9*100,IF(OR(F9<120,F9>220),"",F9)) | T9: =IF(OR(G9<30,G9>250),"",G9) | U9: =IF(OR(H9=-99,H9<70,H9>260),"",H9) | V9: =IF(OR(I9<40,I9>150),"",I9) | W9: =IF(AND(U9<>"",V9<>""),IF(V9>=U9,1,0),0) | X9: =IF(W9=1,"",U9) | Y9: =IF(W9=1,"",V9) | Z9: =IF(Q9="M","",K9) | AA9: =IF(D9>E9,"",D9) | AB9: =IF(AA9="","",DATEDIF(AA9,E9,"y")) | AC9: =IF(AND(P9=1,OR(AB9="",AB9>=18)),1,0) | AD9: =IF(OR(S9="",T9=""),"",T9/(S9/100)^2) | AE9: =IF(AB9="","",IF(AB9<40,1,IF(AB9<60,2,3))) | AF9: =COUNTIF(labs!$A$2:$A$84,B9) | AG9: =IF(AF9=0,"",AVERAGEIF(labs!$A$2:$A$84,B9,labs!$C$2:$C$84))
A10: 9 | B10: 9 | C10: M | D10: 28101 | E10: 45772 | F10: 176 | G10: 7.8 | H10: 133 | I10: 82 | J10: No | L10: 7.2 | M10: =A10&"|"&B10&"|"&C10&"|"&D10&"|"&E10&"|"&F10&"|"&G10&"|"&H10&"|"&I10&"|"&J10&"|"&K10&"|"&L10 | N10: =IF(COUNTIF(M$2:M10,M10)>1,1,0) | O10: =IF(AND(N10=0,COUNTIFS(B$2:B$43,B10,N$2:N$43,0,A$2:A$43,"<"&A10)>0),1,0) | P10: =IF(N10+O10=0,1,0) | Q10: =UPPER(LEFT(TRIM(C10),1)) | R10: =IF(UPPER(LEFT(TRIM(J10),1))="Y","yes",IF(UPPER(LEFT(TRIM(J10),1))="N","no","")) | S10: =IF(F10<3,F10*100,IF(OR(F10<120,F10>220),"",F10)) | T10: =IF(OR(G10<30,G10>250),"",G10) | U10: =IF(OR(H10=-99,H10<70,H10>260),"",H10) | V10: =IF(OR(I10<40,I10>150),"",I10) | W10: =IF(AND(U10<>"",V10<>""),IF(V10>=U10,1,0),0) | X10: =IF(W10=1,"",U10) | Y10: =IF(W10=1,"",V10) | Z10: =IF(Q10="M","",K10) | AA10: =IF(D10>E10,"",D10) | AB10: =IF(AA10="","",DATEDIF(AA10,E10,"y")) | AC10: =IF(AND(P10=1,OR(AB10="",AB10>=18)),1,0) | AD10: =IF(OR(S10="",T10=""),"",T10/(S10/100)^2) | AE10: =IF(AB10="","",IF(AB10<40,1,IF(AB10<60,2,3))) | AF10: =COUNTIF(labs!$A$2:$A$84,B10) | AG10: =IF(AF10=0,"",AVERAGEIF(labs!$A$2:$A$84,B10,labs!$C$2:$C$84))
A11: 10 | B11: 10 | C11: f | D11: 19287 | E11: 45899 | F11: 158 | G11: 71.3 | H11: 114 | I11: 77 | J11: no | K11: no | L11: 7.4 | M11: =A11&"|"&B11&"|"&C11&"|"&D11&"|"&E11&"|"&F11&"|"&G11&"|"&H11&"|"&I11&"|"&J11&"|"&K11&"|"&L11 | N11: =IF(COUNTIF(M$2:M11,M11)>1,1,0) | O11: =IF(AND(N11=0,COUNTIFS(B$2:B$43,B11,N$2:N$43,0,A$2:A$43,"<"&A11)>0),1,0) | P11: =IF(N11+O11=0,1,0) | Q11: =UPPER(LEFT(TRIM(C11),1)) | R11: =IF(UPPER(LEFT(TRIM(J11),1))="Y","yes",IF(UPPER(LEFT(TRIM(J11),1))="N","no","")) | S11: =IF(F11<3,F11*100,IF(OR(F11<120,F11>220),"",F11)) | T11: =IF(OR(G11<30,G11>250),"",G11) | U11: =IF(OR(H11=-99,H11<70,H11>260),"",H11) | V11: =IF(OR(I11<40,I11>150),"",I11) | W11: =IF(AND(U11<>"",V11<>""),IF(V11>=U11,1,0),0) | X11: =IF(W11=1,"",U11) | Y11: =IF(W11=1,"",V11) | Z11: =IF(Q11="M","",K11) | AA11: =IF(D11>E11,"",D11) | AB11: =IF(AA11="","",DATEDIF(AA11,E11,"y")) | AC11: =IF(AND(P11=1,OR(AB11="",AB11>=18)),1,0) | AD11: =IF(OR(S11="",T11=""),"",T11/(S11/100)^2) | AE11: =IF(AB11="","",IF(AB11<40,1,IF(AB11<60,2,3))) | AF11: =COUNTIF(labs!$A$2:$A$84,B11) | AG11: =IF(AF11=0,"",AVERAGEIF(labs!$A$2:$A$84,B11,labs!$C$2:$C$84))
A12: 11 | B12: 11 | C12: M | D12: 34585 | E12: 45867 | F12: 190 | G12: 71.4 | H12: 148 | I12: 84 | J12: no | L12: 8.2 | M12: =A12&"|"&B12&"|"&C12&"|"&D12&"|"&E12&"|"&F12&"|"&G12&"|"&H12&"|"&I12&"|"&J12&"|"&K12&"|"&L12 | N12: =IF(COUNTIF(M$2:M12,M12)>1,1,0) | O12: =IF(AND(N12=0,COUNTIFS(B$2:B$43,B12,N$2:N$43,0,A$2:A$43,"<"&A12)>0),1,0) | P12: =IF(N12+O12=0,1,0) | Q12: =UPPER(LEFT(TRIM(C12),1)) | R12: =IF(UPPER(LEFT(TRIM(J12),1))="Y","yes",IF(UPPER(LEFT(TRIM(J12),1))="N","no","")) | S12: =IF(F12<3,F12*100,IF(OR(F12<120,F12>220),"",F12)) | T12: =IF(OR(G12<30,G12>250),"",G12) | U12: =IF(OR(H12=-99,H12<70,H12>260),"",H12) | V12: =IF(OR(I12<40,I12>150),"",I12) | W12: =IF(AND(U12<>"",V12<>""),IF(V12>=U12,1,0),0) | X12: =IF(W12=1,"",U12) | Y12: =IF(W12=1,"",V12) | Z12: =IF(Q12="M","",K12) | AA12: =IF(D12>E12,"",D12) | AB12: =IF(AA12="","",DATEDIF(AA12,E12,"y")) | AC12: =IF(AND(P12=1,OR(AB12="",AB12>=18)),1,0) | AD12: =IF(OR(S12="",T12=""),"",T12/(S12/100)^2) | AE12: =IF(AB12="","",IF(AB12<40,1,IF(AB12<60,2,3))) | AF12: =COUNTIF(labs!$A$2:$A$84,B12) | AG12: =IF(AF12=0,"",AVERAGEIF(labs!$A$2:$A$84,B12,labs!$C$2:$C$84))
A13: 12 | B13: 12 | C13: F | D13: 27665 | E13: 45818 | F13: 163 | G13: 70.5 | H13: 159 | I13: 98 | J13: no | K13: no | L13: 8.1 | M13: =A13&"|"&B13&"|"&C13&"|"&D13&"|"&E13&"|"&F13&"|"&G13&"|"&H13&"|"&I13&"|"&J13&"|"&K13&"|"&L13 | N13: =IF(COUNTIF(M$2:M13,M13)>1,1,0) | O13: =IF(AND(N13=0,COUNTIFS(B$2:B$43,B13,N$2:N$43,0,A$2:A$43,"<"&A13)>0),1,0) | P13: =IF(N13+O13=0,1,0) | Q13: =UPPER(LEFT(TRIM(C13),1)) | R13: =IF(UPPER(LEFT(TRIM(J13),1))="Y","yes",IF(UPPER(LEFT(TRIM(J13),1))="N","no","")) | S13: =IF(F13<3,F13*100,IF(OR(F13<120,F13>220),"",F13)) | T13: =IF(OR(G13<30,G13>250),"",G13) | U13: =IF(OR(H13=-99,H13<70,H13>260),"",H13) | V13: =IF(OR(I13<40,I13>150),"",I13) | W13: =IF(AND(U13<>"",V13<>""),IF(V13>=U13,1,0),0) | X13: =IF(W13=1,"",U13) | Y13: =IF(W13=1,"",V13) | Z13: =IF(Q13="M","",K13) | AA13: =IF(D13>E13,"",D13) | AB13: =IF(AA13="","",DATEDIF(AA13,E13,"y")) | AC13: =IF(AND(P13=1,OR(AB13="",AB13>=18)),1,0) | AD13: =IF(OR(S13="",T13=""),"",T13/(S13/100)^2) | AE13: =IF(AB13="","",IF(AB13<40,1,IF(AB13<60,2,3))) | AF13: =COUNTIF(labs!$A$2:$A$84,B13) | AG13: =IF(AF13=0,"",AVERAGEIF(labs!$A$2:$A$84,B13,labs!$C$2:$C$84))
A14: 13 | B14: 13 | C14: M | D14: 32839 | E14: 45960 | F14: 173 | G14: 97.8 | H14: 115 | I14: 67 | J14: N | L14: 7 | M14: =A14&"|"&B14&"|"&C14&"|"&D14&"|"&E14&"|"&F14&"|"&G14&"|"&H14&"|"&I14&"|"&J14&"|"&K14&"|"&L14 | N14: =IF(COUNTIF(M$2:M14,M14)>1,1,0) | O14: =IF(AND(N14=0,COUNTIFS(B$2:B$43,B14,N$2:N$43,0,A$2:A$43,"<"&A14)>0),1,0) | P14: =IF(N14+O14=0,1,0) | Q14: =UPPER(LEFT(TRIM(C14),1)) | R14: =IF(UPPER(LEFT(TRIM(J14),1))="Y","yes",IF(UPPER(LEFT(TRIM(J14),1))="N","no","")) | S14: =IF(F14<3,F14*100,IF(OR(F14<120,F14>220),"",F14)) | T14: =IF(OR(G14<30,G14>250),"",G14) | U14: =IF(OR(H14=-99,H14<70,H14>260),"",H14) | V14: =IF(OR(I14<40,I14>150),"",I14) | W14: =IF(AND(U14<>"",V14<>""),IF(V14>=U14,1,0),0) | X14: =IF(W14=1,"",U14) | Y14: =IF(W14=1,"",V14) | Z14: =IF(Q14="M","",K14) | AA14: =IF(D14>E14,"",D14) | AB14: =IF(AA14="","",DATEDIF(AA14,E14,"y")) | AC14: =IF(AND(P14=1,OR(AB14="",AB14>=18)),1,0) | AD14: =IF(OR(S14="",T14=""),"",T14/(S14/100)^2) | AE14: =IF(AB14="","",IF(AB14<40,1,IF(AB14<60,2,3))) | AF14: =COUNTIF(labs!$A$2:$A$84,B14) | AG14: =IF(AF14=0,"",AVERAGEIF(labs!$A$2:$A$84,B14,labs!$C$2:$C$84))
A15: 14 | B15: 14 | C15: M | D15: 26441 | E15: 45782 | F15: 180 | G15: 95.3 | H15: 1450 | I15: 95 | J15: no | L15: 6.5 | M15: =A15&"|"&B15&"|"&C15&"|"&D15&"|"&E15&"|"&F15&"|"&G15&"|"&H15&"|"&I15&"|"&J15&"|"&K15&"|"&L15 | N15: =IF(COUNTIF(M$2:M15,M15)>1,1,0) | O15: =IF(AND(N15=0,COUNTIFS(B$2:B$43,B15,N$2:N$43,0,A$2:A$43,"<"&A15)>0),1,0) | P15: =IF(N15+O15=0,1,0) | Q15: =UPPER(LEFT(TRIM(C15),1)) | R15: =IF(UPPER(LEFT(TRIM(J15),1))="Y","yes",IF(UPPER(LEFT(TRIM(J15),1))="N","no","")) | S15: =IF(F15<3,F15*100,IF(OR(F15<120,F15>220),"",F15)) | T15: =IF(OR(G15<30,G15>250),"",G15) | U15: =IF(OR(H15=-99,H15<70,H15>260),"",H15) | V15: =IF(OR(I15<40,I15>150),"",I15) | W15: =IF(AND(U15<>"",V15<>""),IF(V15>=U15,1,0),0) | X15: =IF(W15=1,"",U15) | Y15: =IF(W15=1,"",V15) | Z15: =IF(Q15="M","",K15) | AA15: =IF(D15>E15,"",D15) | AB15: =IF(AA15="","",DATEDIF(AA15,E15,"y")) | AC15: =IF(AND(P15=1,OR(AB15="",AB15>=18)),1,0) | AD15: =IF(OR(S15="",T15=""),"",T15/(S15/100)^2) | AE15: =IF(AB15="","",IF(AB15<40,1,IF(AB15<60,2,3))) | AF15: =COUNTIF(labs!$A$2:$A$84,B15) | AG15: =IF(AF15=0,"",AVERAGEIF(labs!$A$2:$A$84,B15,labs!$C$2:$C$84))
A16: 15 | B16: 15 | C16: M | D16: 26600 | E16: 45806 | F16: 174 | G16: 74.9 | H16: 148 | I16: 87 | J16: no | L16: 5.7 | M16: =A16&"|"&B16&"|"&C16&"|"&D16&"|"&E16&"|"&F16&"|"&G16&"|"&H16&"|"&I16&"|"&J16&"|"&K16&"|"&L16 | N16: =IF(COUNTIF(M$2:M16,M16)>1,1,0) | O16: =IF(AND(N16=0,COUNTIFS(B$2:B$43,B16,N$2:N$43,0,A$2:A$43,"<"&A16)>0),1,0) | P16: =IF(N16+O16=0,1,0) | Q16: =UPPER(LEFT(TRIM(C16),1)) | R16: =IF(UPPER(LEFT(TRIM(J16),1))="Y","yes",IF(UPPER(LEFT(TRIM(J16),1))="N","no","")) | S16: =IF(F16<3,F16*100,IF(OR(F16<120,F16>220),"",F16)) | T16: =IF(OR(G16<30,G16>250),"",G16) | U16: =IF(OR(H16=-99,H16<70,H16>260),"",H16) | V16: =IF(OR(I16<40,I16>150),"",I16) | W16: =IF(AND(U16<>"",V16<>""),IF(V16>=U16,1,0),0) | X16: =IF(W16=1,"",U16) | Y16: =IF(W16=1,"",V16) | Z16: =IF(Q16="M","",K16) | AA16: =IF(D16>E16,"",D16) | AB16: =IF(AA16="","",DATEDIF(AA16,E16,"y")) | AC16: =IF(AND(P16=1,OR(AB16="",AB16>=18)),1,0) | AD16: =IF(OR(S16="",T16=""),"",T16/(S16/100)^2) | AE16: =IF(AB16="","",IF(AB16<40,1,IF(AB16<60,2,3))) | AF16: =COUNTIF(labs!$A$2:$A$84,B16) | AG16: =IF(AF16=0,"",AVERAGEIF(labs!$A$2:$A$84,B16,labs!$C$2:$C$84))
A17: 16 | B17: 16 | C17: M | D17: 18127 | E17: 45791 | F17: 181 | G17: 89.4 | H17: 165 | I17: 101 | J17: no | L17: 7.2 | M17: =A17&"|"&B17&"|"&C17&"|"&D17&"|"&E17&"|"&F17&"|"&G17&"|"&H17&"|"&I17&"|"&J17&"|"&K17&"|"&L17 | N17: =IF(COUNTIF(M$2:M17,M17)>1,1,0) | O17: =IF(AND(N17=0,COUNTIFS(B$2:B$43,B17,N$2:N$43,0,A$2:A$43,"<"&A17)>0),1,0) | P17: =IF(N17+O17=0,1,0) | Q17: =UPPER(LEFT(TRIM(C17),1)) | R17: =IF(UPPER(LEFT(TRIM(J17),1))="Y","yes",IF(UPPER(LEFT(TRIM(J17),1))="N","no","")) | S17: =IF(F17<3,F17*100,IF(OR(F17<120,F17>220),"",F17)) | T17: =IF(OR(G17<30,G17>250),"",G17) | U17: =IF(OR(H17=-99,H17<70,H17>260),"",H17) | V17: =IF(OR(I17<40,I17>150),"",I17) | W17: =IF(AND(U17<>"",V17<>""),IF(V17>=U17,1,0),0) | X17: =IF(W17=1,"",U17) | Y17: =IF(W17=1,"",V17) | Z17: =IF(Q17="M","",K17) | AA17: =IF(D17>E17,"",D17) | AB17: =IF(AA17="","",DATEDIF(AA17,E17,"y")) | AC17: =IF(AND(P17=1,OR(AB17="",AB17>=18)),1,0) | AD17: =IF(OR(S17="",T17=""),"",T17/(S17/100)^2) | AE17: =IF(AB17="","",IF(AB17<40,1,IF(AB17<60,2,3))) | AF17: =COUNTIF(labs!$A$2:$A$84,B17) | AG17: =IF(AF17=0,"",AVERAGEIF(labs!$A$2:$A$84,B17,labs!$C$2:$C$84))
A18: 17 | B18: 17 | C18: female | D18: 36238 | E18: 45779 | F18: 151 | G18: 76.2 | H18: 123 | I18: 71 | K18: no | L18: 6.4 | M18: =A18&"|"&B18&"|"&C18&"|"&D18&"|"&E18&"|"&F18&"|"&G18&"|"&H18&"|"&I18&"|"&J18&"|"&K18&"|"&L18 | N18: =IF(COUNTIF(M$2:M18,M18)>1,1,0) | O18: =IF(AND(N18=0,COUNTIFS(B$2:B$43,B18,N$2:N$43,0,A$2:A$43,"<"&A18)>0),1,0) | P18: =IF(N18+O18=0,1,0) | Q18: =UPPER(LEFT(TRIM(C18),1)) | R18: =IF(UPPER(LEFT(TRIM(J18),1))="Y","yes",IF(UPPER(LEFT(TRIM(J18),1))="N","no","")) | S18: =IF(F18<3,F18*100,IF(OR(F18<120,F18>220),"",F18)) | T18: =IF(OR(G18<30,G18>250),"",G18) | U18: =IF(OR(H18=-99,H18<70,H18>260),"",H18) | V18: =IF(OR(I18<40,I18>150),"",I18) | W18: =IF(AND(U18<>"",V18<>""),IF(V18>=U18,1,0),0) | X18: =IF(W18=1,"",U18) | Y18: =IF(W18=1,"",V18) | Z18: =IF(Q18="M","",K18) | AA18: =IF(D18>E18,"",D18) | AB18: =IF(AA18="","",DATEDIF(AA18,E18,"y")) | AC18: =IF(AND(P18=1,OR(AB18="",AB18>=18)),1,0) | AD18: =IF(OR(S18="",T18=""),"",T18/(S18/100)^2) | AE18: =IF(AB18="","",IF(AB18<40,1,IF(AB18<60,2,3))) | AF18: =COUNTIF(labs!$A$2:$A$84,B18) | AG18: =IF(AF18=0,"",AVERAGEIF(labs!$A$2:$A$84,B18,labs!$C$2:$C$84))
A19: 18 | B19: 18 | C19: M | D19: 36392 | E19: 45878 | F19: 1720 | G19: 69.8 | H19: 140 | I19: 86 | J19: no | L19: 7.7 | M19: =A19&"|"&B19&"|"&C19&"|"&D19&"|"&E19&"|"&F19&"|"&G19&"|"&H19&"|"&I19&"|"&J19&"|"&K19&"|"&L19 | N19: =IF(COUNTIF(M$2:M19,M19)>1,1,0) | O19: =IF(AND(N19=0,COUNTIFS(B$2:B$43,B19,N$2:N$43,0,A$2:A$43,"<"&A19)>0),1,0) | P19: =IF(N19+O19=0,1,0) | Q19: =UPPER(LEFT(TRIM(C19),1)) | R19: =IF(UPPER(LEFT(TRIM(J19),1))="Y","yes",IF(UPPER(LEFT(TRIM(J19),1))="N","no","")) | S19: =IF(F19<3,F19*100,IF(OR(F19<120,F19>220),"",F19)) | T19: =IF(OR(G19<30,G19>250),"",G19) | U19: =IF(OR(H19=-99,H19<70,H19>260),"",H19) | V19: =IF(OR(I19<40,I19>150),"",I19) | W19: =IF(AND(U19<>"",V19<>""),IF(V19>=U19,1,0),0) | X19: =IF(W19=1,"",U19) | Y19: =IF(W19=1,"",V19) | Z19: =IF(Q19="M","",K19) | AA19: =IF(D19>E19,"",D19) | AB19: =IF(AA19="","",DATEDIF(AA19,E19,"y")) | AC19: =IF(AND(P19=1,OR(AB19="",AB19>=18)),1,0) | AD19: =IF(OR(S19="",T19=""),"",T19/(S19/100)^2) | AE19: =IF(AB19="","",IF(AB19<40,1,IF(AB19<60,2,3))) | AF19: =COUNTIF(labs!$A$2:$A$84,B19) | AG19: =IF(AF19=0,"",AVERAGEIF(labs!$A$2:$A$84,B19,labs!$C$2:$C$84))
A20: 19 | B20: 19 | C20: M | D20: 19067 | E20: 45734 | F20: 179 | G20: 107.7 | H20: 112 | I20: 73 | J20: no | L20: 5.3 | M20: =A20&"|"&B20&"|"&C20&"|"&D20&"|"&E20&"|"&F20&"|"&G20&"|"&H20&"|"&I20&"|"&J20&"|"&K20&"|"&L20 | N20: =IF(COUNTIF(M$2:M20,M20)>1,1,0) | O20: =IF(AND(N20=0,COUNTIFS(B$2:B$43,B20,N$2:N$43,0,A$2:A$43,"<"&A20)>0),1,0) | P20: =IF(N20+O20=0,1,0) | Q20: =UPPER(LEFT(TRIM(C20),1)) | R20: =IF(UPPER(LEFT(TRIM(J20),1))="Y","yes",IF(UPPER(LEFT(TRIM(J20),1))="N","no","")) | S20: =IF(F20<3,F20*100,IF(OR(F20<120,F20>220),"",F20)) | T20: =IF(OR(G20<30,G20>250),"",G20) | U20: =IF(OR(H20=-99,H20<70,H20>260),"",H20) | V20: =IF(OR(I20<40,I20>150),"",I20) | W20: =IF(AND(U20<>"",V20<>""),IF(V20>=U20,1,0),0) | X20: =IF(W20=1,"",U20) | Y20: =IF(W20=1,"",V20) | Z20: =IF(Q20="M","",K20) | AA20: =IF(D20>E20,"",D20) | AB20: =IF(AA20="","",DATEDIF(AA20,E20,"y")) | AC20: =IF(AND(P20=1,OR(AB20="",AB20>=18)),1,0) | AD20: =IF(OR(S20="",T20=""),"",T20/(S20/100)^2) | AE20: =IF(AB20="","",IF(AB20<40,1,IF(AB20<60,2,3))) | AF20: =COUNTIF(labs!$A$2:$A$84,B20) | AG20: =IF(AF20=0,"",AVERAGEIF(labs!$A$2:$A$84,B20,labs!$C$2:$C$84))
A21: 20 | B21: 20 | C21: M | D21: 25237 | E21: 45938 | F21: 166 | G21: 78.8 | H21: 130 | I21: 87 | J21: no | M21: =A21&"|"&B21&"|"&C21&"|"&D21&"|"&E21&"|"&F21&"|"&G21&"|"&H21&"|"&I21&"|"&J21&"|"&K21&"|"&L21 | N21: =IF(COUNTIF(M$2:M21,M21)>1,1,0) | O21: =IF(AND(N21=0,COUNTIFS(B$2:B$43,B21,N$2:N$43,0,A$2:A$43,"<"&A21)>0),1,0) | P21: =IF(N21+O21=0,1,0) | Q21: =UPPER(LEFT(TRIM(C21),1)) | R21: =IF(UPPER(LEFT(TRIM(J21),1))="Y","yes",IF(UPPER(LEFT(TRIM(J21),1))="N","no","")) | S21: =IF(F21<3,F21*100,IF(OR(F21<120,F21>220),"",F21)) | T21: =IF(OR(G21<30,G21>250),"",G21) | U21: =IF(OR(H21=-99,H21<70,H21>260),"",H21) | V21: =IF(OR(I21<40,I21>150),"",I21) | W21: =IF(AND(U21<>"",V21<>""),IF(V21>=U21,1,0),0) | X21: =IF(W21=1,"",U21) | Y21: =IF(W21=1,"",V21) | Z21: =IF(Q21="M","",K21) | AA21: =IF(D21>E21,"",D21) | AB21: =IF(AA21="","",DATEDIF(AA21,E21,"y")) | AC21: =IF(AND(P21=1,OR(AB21="",AB21>=18)),1,0) | AD21: =IF(OR(S21="",T21=""),"",T21/(S21/100)^2) | AE21: =IF(AB21="","",IF(AB21<40,1,IF(AB21<60,2,3))) | AF21: =COUNTIF(labs!$A$2:$A$84,B21) | AG21: =IF(AF21=0,"",AVERAGEIF(labs!$A$2:$A$84,B21,labs!$C$2:$C$84))
A22: 21 | B22: 21 | C22: M | D22: 19414 | E22: 45944 | F22: 186 | G22: 100.8 | H22: 159 | I22: 92 | J22: NO | L22: 7 | M22: =A22&"|"&B22&"|"&C22&"|"&D22&"|"&E22&"|"&F22&"|"&G22&"|"&H22&"|"&I22&"|"&J22&"|"&K22&"|"&L22 | N22: =IF(COUNTIF(M$2:M22,M22)>1,1,0) | O22: =IF(AND(N22=0,COUNTIFS(B$2:B$43,B22,N$2:N$43,0,A$2:A$43,"<"&A22)>0),1,0) | P22: =IF(N22+O22=0,1,0) | Q22: =UPPER(LEFT(TRIM(C22),1)) | R22: =IF(UPPER(LEFT(TRIM(J22),1))="Y","yes",IF(UPPER(LEFT(TRIM(J22),1))="N","no","")) | S22: =IF(F22<3,F22*100,IF(OR(F22<120,F22>220),"",F22)) | T22: =IF(OR(G22<30,G22>250),"",G22) | U22: =IF(OR(H22=-99,H22<70,H22>260),"",H22) | V22: =IF(OR(I22<40,I22>150),"",I22) | W22: =IF(AND(U22<>"",V22<>""),IF(V22>=U22,1,0),0) | X22: =IF(W22=1,"",U22) | Y22: =IF(W22=1,"",V22) | Z22: =IF(Q22="M","",K22) | AA22: =IF(D22>E22,"",D22) | AB22: =IF(AA22="","",DATEDIF(AA22,E22,"y")) | AC22: =IF(AND(P22=1,OR(AB22="",AB22>=18)),1,0) | AD22: =IF(OR(S22="",T22=""),"",T22/(S22/100)^2) | AE22: =IF(AB22="","",IF(AB22<40,1,IF(AB22<60,2,3))) | AF22: =COUNTIF(labs!$A$2:$A$84,B22) | AG22: =IF(AF22=0,"",AVERAGEIF(labs!$A$2:$A$84,B22,labs!$C$2:$C$84))
A23: 22 | B23: 22 | C23: F | D23: 17876 | E23: 45746 | F23: 157 | G23: 72.3 | H23: 88 | I23: 95 | J23: no | K23: no | L23: 5.9 | M23: =A23&"|"&B23&"|"&C23&"|"&D23&"|"&E23&"|"&F23&"|"&G23&"|"&H23&"|"&I23&"|"&J23&"|"&K23&"|"&L23 | N23: =IF(COUNTIF(M$2:M23,M23)>1,1,0) | O23: =IF(AND(N23=0,COUNTIFS(B$2:B$43,B23,N$2:N$43,0,A$2:A$43,"<"&A23)>0),1,0) | P23: =IF(N23+O23=0,1,0) | Q23: =UPPER(LEFT(TRIM(C23),1)) | R23: =IF(UPPER(LEFT(TRIM(J23),1))="Y","yes",IF(UPPER(LEFT(TRIM(J23),1))="N","no","")) | S23: =IF(F23<3,F23*100,IF(OR(F23<120,F23>220),"",F23)) | T23: =IF(OR(G23<30,G23>250),"",G23) | U23: =IF(OR(H23=-99,H23<70,H23>260),"",H23) | V23: =IF(OR(I23<40,I23>150),"",I23) | W23: =IF(AND(U23<>"",V23<>""),IF(V23>=U23,1,0),0) | X23: =IF(W23=1,"",U23) | Y23: =IF(W23=1,"",V23) | Z23: =IF(Q23="M","",K23) | AA23: =IF(D23>E23,"",D23) | AB23: =IF(AA23="","",DATEDIF(AA23,E23,"y")) | AC23: =IF(AND(P23=1,OR(AB23="",AB23>=18)),1,0) | AD23: =IF(OR(S23="",T23=""),"",T23/(S23/100)^2) | AE23: =IF(AB23="","",IF(AB23<40,1,IF(AB23<60,2,3))) | AF23: =COUNTIF(labs!$A$2:$A$84,B23) | AG23: =IF(AF23=0,"",AVERAGEIF(labs!$A$2:$A$84,B23,labs!$C$2:$C$84))
A24: 23 | B24: 23 | C24: M | D24: 28654 | E24: 45961 | F24: 175 | G24: 86.8 | H24: 153 | I24: 96 | J24: no | L24: 6.7 | M24: =A24&"|"&B24&"|"&C24&"|"&D24&"|"&E24&"|"&F24&"|"&G24&"|"&H24&"|"&I24&"|"&J24&"|"&K24&"|"&L24 | N24: =IF(COUNTIF(M$2:M24,M24)>1,1,0) | O24: =IF(AND(N24=0,COUNTIFS(B$2:B$43,B24,N$2:N$43,0,A$2:A$43,"<"&A24)>0),1,0) | P24: =IF(N24+O24=0,1,0) | Q24: =UPPER(LEFT(TRIM(C24),1)) | R24: =IF(UPPER(LEFT(TRIM(J24),1))="Y","yes",IF(UPPER(LEFT(TRIM(J24),1))="N","no","")) | S24: =IF(F24<3,F24*100,IF(OR(F24<120,F24>220),"",F24)) | T24: =IF(OR(G24<30,G24>250),"",G24) | U24: =IF(OR(H24=-99,H24<70,H24>260),"",H24) | V24: =IF(OR(I24<40,I24>150),"",I24) | W24: =IF(AND(U24<>"",V24<>""),IF(V24>=U24,1,0),0) | X24: =IF(W24=1,"",U24) | Y24: =IF(W24=1,"",V24) | Z24: =IF(Q24="M","",K24) | AA24: =IF(D24>E24,"",D24) | AB24: =IF(AA24="","",DATEDIF(AA24,E24,"y")) | AC24: =IF(AND(P24=1,OR(AB24="",AB24>=18)),1,0) | AD24: =IF(OR(S24="",T24=""),"",T24/(S24/100)^2) | AE24: =IF(AB24="","",IF(AB24<40,1,IF(AB24<60,2,3))) | AF24: =COUNTIF(labs!$A$2:$A$84,B24) | AG24: =IF(AF24=0,"",AVERAGEIF(labs!$A$2:$A$84,B24,labs!$C$2:$C$84))
A25: 24 | B25: 24 | C25: M | D25: 32726 | E25: 45701 | F25: 163 | G25: 57.5 | H25: 145 | I25: 83 | J25: Y | L25: 8.2 | M25: =A25&"|"&B25&"|"&C25&"|"&D25&"|"&E25&"|"&F25&"|"&G25&"|"&H25&"|"&I25&"|"&J25&"|"&K25&"|"&L25 | N25: =IF(COUNTIF(M$2:M25,M25)>1,1,0) | O25: =IF(AND(N25=0,COUNTIFS(B$2:B$43,B25,N$2:N$43,0,A$2:A$43,"<"&A25)>0),1,0) | P25: =IF(N25+O25=0,1,0) | Q25: =UPPER(LEFT(TRIM(C25),1)) | R25: =IF(UPPER(LEFT(TRIM(J25),1))="Y","yes",IF(UPPER(LEFT(TRIM(J25),1))="N","no","")) | S25: =IF(F25<3,F25*100,IF(OR(F25<120,F25>220),"",F25)) | T25: =IF(OR(G25<30,G25>250),"",G25) | U25: =IF(OR(H25=-99,H25<70,H25>260),"",H25) | V25: =IF(OR(I25<40,I25>150),"",I25) | W25: =IF(AND(U25<>"",V25<>""),IF(V25>=U25,1,0),0) | X25: =IF(W25=1,"",U25) | Y25: =IF(W25=1,"",V25) | Z25: =IF(Q25="M","",K25) | AA25: =IF(D25>E25,"",D25) | AB25: =IF(AA25="","",DATEDIF(AA25,E25,"y")) | AC25: =IF(AND(P25=1,OR(AB25="",AB25>=18)),1,0) | AD25: =IF(OR(S25="",T25=""),"",T25/(S25/100)^2) | AE25: =IF(AB25="","",IF(AB25<40,1,IF(AB25<60,2,3))) | AF25: =COUNTIF(labs!$A$2:$A$84,B25) | AG25: =IF(AF25=0,"",AVERAGEIF(labs!$A$2:$A$84,B25,labs!$C$2:$C$84))
A26: 25 | B26: 25 | C26: M | D26: 26893 | E26: 45855 | F26: 168 | G26: 77.1 | H26: 142 | I26: 92 | J26: no | L26: 8.2 | M26: =A26&"|"&B26&"|"&C26&"|"&D26&"|"&E26&"|"&F26&"|"&G26&"|"&H26&"|"&I26&"|"&J26&"|"&K26&"|"&L26 | N26: =IF(COUNTIF(M$2:M26,M26)>1,1,0) | O26: =IF(AND(N26=0,COUNTIFS(B$2:B$43,B26,N$2:N$43,0,A$2:A$43,"<"&A26)>0),1,0) | P26: =IF(N26+O26=0,1,0) | Q26: =UPPER(LEFT(TRIM(C26),1)) | R26: =IF(UPPER(LEFT(TRIM(J26),1))="Y","yes",IF(UPPER(LEFT(TRIM(J26),1))="N","no","")) | S26: =IF(F26<3,F26*100,IF(OR(F26<120,F26>220),"",F26)) | T26: =IF(OR(G26<30,G26>250),"",G26) | U26: =IF(OR(H26=-99,H26<70,H26>260),"",H26) | V26: =IF(OR(I26<40,I26>150),"",I26) | W26: =IF(AND(U26<>"",V26<>""),IF(V26>=U26,1,0),0) | X26: =IF(W26=1,"",U26) | Y26: =IF(W26=1,"",V26) | Z26: =IF(Q26="M","",K26) | AA26: =IF(D26>E26,"",D26) | AB26: =IF(AA26="","",DATEDIF(AA26,E26,"y")) | AC26: =IF(AND(P26=1,OR(AB26="",AB26>=18)),1,0) | AD26: =IF(OR(S26="",T26=""),"",T26/(S26/100)^2) | AE26: =IF(AB26="","",IF(AB26<40,1,IF(AB26<60,2,3))) | AF26: =COUNTIF(labs!$A$2:$A$84,B26) | AG26: =IF(AF26=0,"",AVERAGEIF(labs!$A$2:$A$84,B26,labs!$C$2:$C$84))
A27: 26 | B27: 26 | C27: M | D27: 35720 | E27: 45718 | F27: 178 | G27: 102.7 | H27: 157 | I27: 89 | J27: no | L27: 5.8 | M27: =A27&"|"&B27&"|"&C27&"|"&D27&"|"&E27&"|"&F27&"|"&G27&"|"&H27&"|"&I27&"|"&J27&"|"&K27&"|"&L27 | N27: =IF(COUNTIF(M$2:M27,M27)>1,1,0) | O27: =IF(AND(N27=0,COUNTIFS(B$2:B$43,B27,N$2:N$43,0,A$2:A$43,"<"&A27)>0),1,0) | P27: =IF(N27+O27=0,1,0) | Q27: =UPPER(LEFT(TRIM(C27),1)) | R27: =IF(UPPER(LEFT(TRIM(J27),1))="Y","yes",IF(UPPER(LEFT(TRIM(J27),1))="N","no","")) | S27: =IF(F27<3,F27*100,IF(OR(F27<120,F27>220),"",F27)) | T27: =IF(OR(G27<30,G27>250),"",G27) | U27: =IF(OR(H27=-99,H27<70,H27>260),"",H27) | V27: =IF(OR(I27<40,I27>150),"",I27) | W27: =IF(AND(U27<>"",V27<>""),IF(V27>=U27,1,0),0) | X27: =IF(W27=1,"",U27) | Y27: =IF(W27=1,"",V27) | Z27: =IF(Q27="M","",K27) | AA27: =IF(D27>E27,"",D27) | AB27: =IF(AA27="","",DATEDIF(AA27,E27,"y")) | AC27: =IF(AND(P27=1,OR(AB27="",AB27>=18)),1,0) | AD27: =IF(OR(S27="",T27=""),"",T27/(S27/100)^2) | AE27: =IF(AB27="","",IF(AB27<40,1,IF(AB27<60,2,3))) | AF27: =COUNTIF(labs!$A$2:$A$84,B27) | AG27: =IF(AF27=0,"",AVERAGEIF(labs!$A$2:$A$84,B27,labs!$C$2:$C$84))
A28: 27 | B28: 27 | C28: M | D28: 29163 | E28: 45722 | F28: 170 | G28: 54.3 | H28: 139 | I28: 83 | J28: yes | L28: 7.5 | M28: =A28&"|"&B28&"|"&C28&"|"&D28&"|"&E28&"|"&F28&"|"&G28&"|"&H28&"|"&I28&"|"&J28&"|"&K28&"|"&L28 | N28: =IF(COUNTIF(M$2:M28,M28)>1,1,0) | O28: =IF(AND(N28=0,COUNTIFS(B$2:B$43,B28,N$2:N$43,0,A$2:A$43,"<"&A28)>0),1,0) | P28: =IF(N28+O28=0,1,0) | Q28: =UPPER(LEFT(TRIM(C28),1)) | R28: =IF(UPPER(LEFT(TRIM(J28),1))="Y","yes",IF(UPPER(LEFT(TRIM(J28),1))="N","no","")) | S28: =IF(F28<3,F28*100,IF(OR(F28<120,F28>220),"",F28)) | T28: =IF(OR(G28<30,G28>250),"",G28) | U28: =IF(OR(H28=-99,H28<70,H28>260),"",H28) | V28: =IF(OR(I28<40,I28>150),"",I28) | W28: =IF(AND(U28<>"",V28<>""),IF(V28>=U28,1,0),0) | X28: =IF(W28=1,"",U28) | Y28: =IF(W28=1,"",V28) | Z28: =IF(Q28="M","",K28) | AA28: =IF(D28>E28,"",D28) | AB28: =IF(AA28="","",DATEDIF(AA28,E28,"y")) | AC28: =IF(AND(P28=1,OR(AB28="",AB28>=18)),1,0) | AD28: =IF(OR(S28="",T28=""),"",T28/(S28/100)^2) | AE28: =IF(AB28="","",IF(AB28<40,1,IF(AB28<60,2,3))) | AF28: =COUNTIF(labs!$A$2:$A$84,B28) | AG28: =IF(AF28=0,"",AVERAGEIF(labs!$A$2:$A$84,B28,labs!$C$2:$C$84))
A29: 28 | B29: 28 | C29: M | D29: 34512 | E29: 45867 | F29: 173 | G29: 86.5 | H29: 166 | I29: 104 | J29: no | L29: 7.1 | M29: =A29&"|"&B29&"|"&C29&"|"&D29&"|"&E29&"|"&F29&"|"&G29&"|"&H29&"|"&I29&"|"&J29&"|"&K29&"|"&L29 | N29: =IF(COUNTIF(M$2:M29,M29)>1,1,0) | O29: =IF(AND(N29=0,COUNTIFS(B$2:B$43,B29,N$2:N$43,0,A$2:A$43,"<"&A29)>0),1,0) | P29: =IF(N29+O29=0,1,0) | Q29: =UPPER(LEFT(TRIM(C29),1)) | R29: =IF(UPPER(LEFT(TRIM(J29),1))="Y","yes",IF(UPPER(LEFT(TRIM(J29),1))="N","no","")) | S29: =IF(F29<3,F29*100,IF(OR(F29<120,F29>220),"",F29)) | T29: =IF(OR(G29<30,G29>250),"",G29) | U29: =IF(OR(H29=-99,H29<70,H29>260),"",H29) | V29: =IF(OR(I29<40,I29>150),"",I29) | W29: =IF(AND(U29<>"",V29<>""),IF(V29>=U29,1,0),0) | X29: =IF(W29=1,"",U29) | Y29: =IF(W29=1,"",V29) | Z29: =IF(Q29="M","",K29) | AA29: =IF(D29>E29,"",D29) | AB29: =IF(AA29="","",DATEDIF(AA29,E29,"y")) | AC29: =IF(AND(P29=1,OR(AB29="",AB29>=18)),1,0) | AD29: =IF(OR(S29="",T29=""),"",T29/(S29/100)^2) | AE29: =IF(AB29="","",IF(AB29<40,1,IF(AB29<60,2,3))) | AF29: =COUNTIF(labs!$A$2:$A$84,B29) | AG29: =IF(AF29=0,"",AVERAGEIF(labs!$A$2:$A$84,B29,labs!$C$2:$C$84))
A30: 29 | B30: 29 | C30: M | D30: 35670 | E30: 45940 | F30: 186 | G30: 87.4 | H30: 153 | I30: 90 | J30: no | M30: =A30&"|"&B30&"|"&C30&"|"&D30&"|"&E30&"|"&F30&"|"&G30&"|"&H30&"|"&I30&"|"&J30&"|"&K30&"|"&L30 | N30: =IF(COUNTIF(M$2:M30,M30)>1,1,0) | O30: =IF(AND(N30=0,COUNTIFS(B$2:B$43,B30,N$2:N$43,0,A$2:A$43,"<"&A30)>0),1,0) | P30: =IF(N30+O30=0,1,0) | Q30: =UPPER(LEFT(TRIM(C30),1)) | R30: =IF(UPPER(LEFT(TRIM(J30),1))="Y","yes",IF(UPPER(LEFT(TRIM(J30),1))="N","no","")) | S30: =IF(F30<3,F30*100,IF(OR(F30<120,F30>220),"",F30)) | T30: =IF(OR(G30<30,G30>250),"",G30) | U30: =IF(OR(H30=-99,H30<70,H30>260),"",H30) | V30: =IF(OR(I30<40,I30>150),"",I30) | W30: =IF(AND(U30<>"",V30<>""),IF(V30>=U30,1,0),0) | X30: =IF(W30=1,"",U30) | Y30: =IF(W30=1,"",V30) | Z30: =IF(Q30="M","",K30) | AA30: =IF(D30>E30,"",D30) | AB30: =IF(AA30="","",DATEDIF(AA30,E30,"y")) | AC30: =IF(AND(P30=1,OR(AB30="",AB30>=18)),1,0) | AD30: =IF(OR(S30="",T30=""),"",T30/(S30/100)^2) | AE30: =IF(AB30="","",IF(AB30<40,1,IF(AB30<60,2,3))) | AF30: =COUNTIF(labs!$A$2:$A$84,B30) | AG30: =IF(AF30=0,"",AVERAGEIF(labs!$A$2:$A$84,B30,labs!$C$2:$C$84))
A31: 30 | B31: 30 | C31: f | D31: 32257 | E31: 45868 | F31: 162 | G31: 78 | H31: 163 | I31: 100 | J31: no | K31: no | L31: 7.4 | M31: =A31&"|"&B31&"|"&C31&"|"&D31&"|"&E31&"|"&F31&"|"&G31&"|"&H31&"|"&I31&"|"&J31&"|"&K31&"|"&L31 | N31: =IF(COUNTIF(M$2:M31,M31)>1,1,0) | O31: =IF(AND(N31=0,COUNTIFS(B$2:B$43,B31,N$2:N$43,0,A$2:A$43,"<"&A31)>0),1,0) | P31: =IF(N31+O31=0,1,0) | Q31: =UPPER(LEFT(TRIM(C31),1)) | R31: =IF(UPPER(LEFT(TRIM(J31),1))="Y","yes",IF(UPPER(LEFT(TRIM(J31),1))="N","no","")) | S31: =IF(F31<3,F31*100,IF(OR(F31<120,F31>220),"",F31)) | T31: =IF(OR(G31<30,G31>250),"",G31) | U31: =IF(OR(H31=-99,H31<70,H31>260),"",H31) | V31: =IF(OR(I31<40,I31>150),"",I31) | W31: =IF(AND(U31<>"",V31<>""),IF(V31>=U31,1,0),0) | X31: =IF(W31=1,"",U31) | Y31: =IF(W31=1,"",V31) | Z31: =IF(Q31="M","",K31) | AA31: =IF(D31>E31,"",D31) | AB31: =IF(AA31="","",DATEDIF(AA31,E31,"y")) | AC31: =IF(AND(P31=1,OR(AB31="",AB31>=18)),1,0) | AD31: =IF(OR(S31="",T31=""),"",T31/(S31/100)^2) | AE31: =IF(AB31="","",IF(AB31<40,1,IF(AB31<60,2,3))) | AF31: =COUNTIF(labs!$A$2:$A$84,B31) | AG31: =IF(AF31=0,"",AVERAGEIF(labs!$A$2:$A$84,B31,labs!$C$2:$C$84))
A32: 31 | B32: 31 | C32: M | D32: 27933 | E32: 45709 | F32: 173 | G32: 62.8 | H32: -99 | I32: 73 | J32: no | L32: 7.2 | M32: =A32&"|"&B32&"|"&C32&"|"&D32&"|"&E32&"|"&F32&"|"&G32&"|"&H32&"|"&I32&"|"&J32&"|"&K32&"|"&L32 | N32: =IF(COUNTIF(M$2:M32,M32)>1,1,0) | O32: =IF(AND(N32=0,COUNTIFS(B$2:B$43,B32,N$2:N$43,0,A$2:A$43,"<"&A32)>0),1,0) | P32: =IF(N32+O32=0,1,0) | Q32: =UPPER(LEFT(TRIM(C32),1)) | R32: =IF(UPPER(LEFT(TRIM(J32),1))="Y","yes",IF(UPPER(LEFT(TRIM(J32),1))="N","no","")) | S32: =IF(F32<3,F32*100,IF(OR(F32<120,F32>220),"",F32)) | T32: =IF(OR(G32<30,G32>250),"",G32) | U32: =IF(OR(H32=-99,H32<70,H32>260),"",H32) | V32: =IF(OR(I32<40,I32>150),"",I32) | W32: =IF(AND(U32<>"",V32<>""),IF(V32>=U32,1,0),0) | X32: =IF(W32=1,"",U32) | Y32: =IF(W32=1,"",V32) | Z32: =IF(Q32="M","",K32) | AA32: =IF(D32>E32,"",D32) | AB32: =IF(AA32="","",DATEDIF(AA32,E32,"y")) | AC32: =IF(AND(P32=1,OR(AB32="",AB32>=18)),1,0) | AD32: =IF(OR(S32="",T32=""),"",T32/(S32/100)^2) | AE32: =IF(AB32="","",IF(AB32<40,1,IF(AB32<60,2,3))) | AF32: =COUNTIF(labs!$A$2:$A$84,B32) | AG32: =IF(AF32=0,"",AVERAGEIF(labs!$A$2:$A$84,B32,labs!$C$2:$C$84))
A33: 32 | B33: 32 | C33: F | D33: 23993 | E33: 45883 | F33: 146 | G33: 62.2 | H33: 138 | I33: 90 | J33: Yes | K33: no | L33: 7.6 | M33: =A33&"|"&B33&"|"&C33&"|"&D33&"|"&E33&"|"&F33&"|"&G33&"|"&H33&"|"&I33&"|"&J33&"|"&K33&"|"&L33 | N33: =IF(COUNTIF(M$2:M33,M33)>1,1,0) | O33: =IF(AND(N33=0,COUNTIFS(B$2:B$43,B33,N$2:N$43,0,A$2:A$43,"<"&A33)>0),1,0) | P33: =IF(N33+O33=0,1,0) | Q33: =UPPER(LEFT(TRIM(C33),1)) | R33: =IF(UPPER(LEFT(TRIM(J33),1))="Y","yes",IF(UPPER(LEFT(TRIM(J33),1))="N","no","")) | S33: =IF(F33<3,F33*100,IF(OR(F33<120,F33>220),"",F33)) | T33: =IF(OR(G33<30,G33>250),"",G33) | U33: =IF(OR(H33=-99,H33<70,H33>260),"",H33) | V33: =IF(OR(I33<40,I33>150),"",I33) | W33: =IF(AND(U33<>"",V33<>""),IF(V33>=U33,1,0),0) | X33: =IF(W33=1,"",U33) | Y33: =IF(W33=1,"",V33) | Z33: =IF(Q33="M","",K33) | AA33: =IF(D33>E33,"",D33) | AB33: =IF(AA33="","",DATEDIF(AA33,E33,"y")) | AC33: =IF(AND(P33=1,OR(AB33="",AB33>=18)),1,0) | AD33: =IF(OR(S33="",T33=""),"",T33/(S33/100)^2) | AE33: =IF(AB33="","",IF(AB33<40,1,IF(AB33<60,2,3))) | AF33: =COUNTIF(labs!$A$2:$A$84,B33) | AG33: =IF(AF33=0,"",AVERAGEIF(labs!$A$2:$A$84,B33,labs!$C$2:$C$84))
A34: 33 | B34: 33 | C34: F | D34: 36323 | E34: 45711 | F34: 168 | G34: 69 | H34: 129 | I34: 80 | J34: no | K34: yes | L34: 6.3 | M34: =A34&"|"&B34&"|"&C34&"|"&D34&"|"&E34&"|"&F34&"|"&G34&"|"&H34&"|"&I34&"|"&J34&"|"&K34&"|"&L34 | N34: =IF(COUNTIF(M$2:M34,M34)>1,1,0) | O34: =IF(AND(N34=0,COUNTIFS(B$2:B$43,B34,N$2:N$43,0,A$2:A$43,"<"&A34)>0),1,0) | P34: =IF(N34+O34=0,1,0) | Q34: =UPPER(LEFT(TRIM(C34),1)) | R34: =IF(UPPER(LEFT(TRIM(J34),1))="Y","yes",IF(UPPER(LEFT(TRIM(J34),1))="N","no","")) | S34: =IF(F34<3,F34*100,IF(OR(F34<120,F34>220),"",F34)) | T34: =IF(OR(G34<30,G34>250),"",G34) | U34: =IF(OR(H34=-99,H34<70,H34>260),"",H34) | V34: =IF(OR(I34<40,I34>150),"",I34) | W34: =IF(AND(U34<>"",V34<>""),IF(V34>=U34,1,0),0) | X34: =IF(W34=1,"",U34) | Y34: =IF(W34=1,"",V34) | Z34: =IF(Q34="M","",K34) | AA34: =IF(D34>E34,"",D34) | AB34: =IF(AA34="","",DATEDIF(AA34,E34,"y")) | AC34: =IF(AND(P34=1,OR(AB34="",AB34>=18)),1,0) | AD34: =IF(OR(S34="",T34=""),"",T34/(S34/100)^2) | AE34: =IF(AB34="","",IF(AB34<40,1,IF(AB34<60,2,3))) | AF34: =COUNTIF(labs!$A$2:$A$84,B34) | AG34: =IF(AF34=0,"",AVERAGEIF(labs!$A$2:$A$84,B34,labs!$C$2:$C$84))
A35: 34 | B35: 34 | C35: F | D35: 30079 | E35: 45808 | F35: 151 | G35: 65.3 | H35: 125 | I35: 72 | J35: no | K35: no | L35: 6.6 | M35: =A35&"|"&B35&"|"&C35&"|"&D35&"|"&E35&"|"&F35&"|"&G35&"|"&H35&"|"&I35&"|"&J35&"|"&K35&"|"&L35 | N35: =IF(COUNTIF(M$2:M35,M35)>1,1,0) | O35: =IF(AND(N35=0,COUNTIFS(B$2:B$43,B35,N$2:N$43,0,A$2:A$43,"<"&A35)>0),1,0) | P35: =IF(N35+O35=0,1,0) | Q35: =UPPER(LEFT(TRIM(C35),1)) | R35: =IF(UPPER(LEFT(TRIM(J35),1))="Y","yes",IF(UPPER(LEFT(TRIM(J35),1))="N","no","")) | S35: =IF(F35<3,F35*100,IF(OR(F35<120,F35>220),"",F35)) | T35: =IF(OR(G35<30,G35>250),"",G35) | U35: =IF(OR(H35=-99,H35<70,H35>260),"",H35) | V35: =IF(OR(I35<40,I35>150),"",I35) | W35: =IF(AND(U35<>"",V35<>""),IF(V35>=U35,1,0),0) | X35: =IF(W35=1,"",U35) | Y35: =IF(W35=1,"",V35) | Z35: =IF(Q35="M","",K35) | AA35: =IF(D35>E35,"",D35) | AB35: =IF(AA35="","",DATEDIF(AA35,E35,"y")) | AC35: =IF(AND(P35=1,OR(AB35="",AB35>=18)),1,0) | AD35: =IF(OR(S35="",T35=""),"",T35/(S35/100)^2) | AE35: =IF(AB35="","",IF(AB35<40,1,IF(AB35<60,2,3))) | AF35: =COUNTIF(labs!$A$2:$A$84,B35) | AG35: =IF(AF35=0,"",AVERAGEIF(labs!$A$2:$A$84,B35,labs!$C$2:$C$84))
A36: 35 | B36: 35 | C36: F | D36: 47970 | E36: 45677 | F36: 163 | G36: 48.6 | H36: 154 | I36: 87 | J36: no | K36: no | L36: 6.3 | M36: =A36&"|"&B36&"|"&C36&"|"&D36&"|"&E36&"|"&F36&"|"&G36&"|"&H36&"|"&I36&"|"&J36&"|"&K36&"|"&L36 | N36: =IF(COUNTIF(M$2:M36,M36)>1,1,0) | O36: =IF(AND(N36=0,COUNTIFS(B$2:B$43,B36,N$2:N$43,0,A$2:A$43,"<"&A36)>0),1,0) | P36: =IF(N36+O36=0,1,0) | Q36: =UPPER(LEFT(TRIM(C36),1)) | R36: =IF(UPPER(LEFT(TRIM(J36),1))="Y","yes",IF(UPPER(LEFT(TRIM(J36),1))="N","no","")) | S36: =IF(F36<3,F36*100,IF(OR(F36<120,F36>220),"",F36)) | T36: =IF(OR(G36<30,G36>250),"",G36) | U36: =IF(OR(H36=-99,H36<70,H36>260),"",H36) | V36: =IF(OR(I36<40,I36>150),"",I36) | W36: =IF(AND(U36<>"",V36<>""),IF(V36>=U36,1,0),0) | X36: =IF(W36=1,"",U36) | Y36: =IF(W36=1,"",V36) | Z36: =IF(Q36="M","",K36) | AA36: =IF(D36>E36,"",D36) | AB36: =IF(AA36="","",DATEDIF(AA36,E36,"y")) | AC36: =IF(AND(P36=1,OR(AB36="",AB36>=18)),1,0) | AD36: =IF(OR(S36="",T36=""),"",T36/(S36/100)^2) | AE36: =IF(AB36="","",IF(AB36<40,1,IF(AB36<60,2,3))) | AF36: =COUNTIF(labs!$A$2:$A$84,B36) | AG36: =IF(AF36=0,"",AVERAGEIF(labs!$A$2:$A$84,B36,labs!$C$2:$C$84))
A37: 36 | B37: 36 | C37: M | D37: 19549 | E37: 45958 | F37: 169 | G37: 107.1 | H37: 120 | I37: 67 | J37: no | L37: 6.5 | M37: =A37&"|"&B37&"|"&C37&"|"&D37&"|"&E37&"|"&F37&"|"&G37&"|"&H37&"|"&I37&"|"&J37&"|"&K37&"|"&L37 | N37: =IF(COUNTIF(M$2:M37,M37)>1,1,0) | O37: =IF(AND(N37=0,COUNTIFS(B$2:B$43,B37,N$2:N$43,0,A$2:A$43,"<"&A37)>0),1,0) | P37: =IF(N37+O37=0,1,0) | Q37: =UPPER(LEFT(TRIM(C37),1)) | R37: =IF(UPPER(LEFT(TRIM(J37),1))="Y","yes",IF(UPPER(LEFT(TRIM(J37),1))="N","no","")) | S37: =IF(F37<3,F37*100,IF(OR(F37<120,F37>220),"",F37)) | T37: =IF(OR(G37<30,G37>250),"",G37) | U37: =IF(OR(H37=-99,H37<70,H37>260),"",H37) | V37: =IF(OR(I37<40,I37>150),"",I37) | W37: =IF(AND(U37<>"",V37<>""),IF(V37>=U37,1,0),0) | X37: =IF(W37=1,"",U37) | Y37: =IF(W37=1,"",V37) | Z37: =IF(Q37="M","",K37) | AA37: =IF(D37>E37,"",D37) | AB37: =IF(AA37="","",DATEDIF(AA37,E37,"y")) | AC37: =IF(AND(P37=1,OR(AB37="",AB37>=18)),1,0) | AD37: =IF(OR(S37="",T37=""),"",T37/(S37/100)^2) | AE37: =IF(AB37="","",IF(AB37<40,1,IF(AB37<60,2,3))) | AF37: =COUNTIF(labs!$A$2:$A$84,B37) | AG37: =IF(AF37=0,"",AVERAGEIF(labs!$A$2:$A$84,B37,labs!$C$2:$C$84))
A38: 37 | B38: 37 | C38: F | D38: 35618 | E38: 45737 | F38: 163 | G38: 66.2 | H38: 140 | I38: 76 | J38: no | K38: yes | L38: 7.7 | M38: =A38&"|"&B38&"|"&C38&"|"&D38&"|"&E38&"|"&F38&"|"&G38&"|"&H38&"|"&I38&"|"&J38&"|"&K38&"|"&L38 | N38: =IF(COUNTIF(M$2:M38,M38)>1,1,0) | O38: =IF(AND(N38=0,COUNTIFS(B$2:B$43,B38,N$2:N$43,0,A$2:A$43,"<"&A38)>0),1,0) | P38: =IF(N38+O38=0,1,0) | Q38: =UPPER(LEFT(TRIM(C38),1)) | R38: =IF(UPPER(LEFT(TRIM(J38),1))="Y","yes",IF(UPPER(LEFT(TRIM(J38),1))="N","no","")) | S38: =IF(F38<3,F38*100,IF(OR(F38<120,F38>220),"",F38)) | T38: =IF(OR(G38<30,G38>250),"",G38) | U38: =IF(OR(H38=-99,H38<70,H38>260),"",H38) | V38: =IF(OR(I38<40,I38>150),"",I38) | W38: =IF(AND(U38<>"",V38<>""),IF(V38>=U38,1,0),0) | X38: =IF(W38=1,"",U38) | Y38: =IF(W38=1,"",V38) | Z38: =IF(Q38="M","",K38) | AA38: =IF(D38>E38,"",D38) | AB38: =IF(AA38="","",DATEDIF(AA38,E38,"y")) | AC38: =IF(AND(P38=1,OR(AB38="",AB38>=18)),1,0) | AD38: =IF(OR(S38="",T38=""),"",T38/(S38/100)^2) | AE38: =IF(AB38="","",IF(AB38<40,1,IF(AB38<60,2,3))) | AF38: =COUNTIF(labs!$A$2:$A$84,B38) | AG38: =IF(AF38=0,"",AVERAGEIF(labs!$A$2:$A$84,B38,labs!$C$2:$C$84))
A39: 38 | B39: 38 | C39: M | D39: 30878 | E39: 45952 | F39: 186 | G39: 97 | H39: 129 | I39: 73 | J39: no | L39: 8.8 | M39: =A39&"|"&B39&"|"&C39&"|"&D39&"|"&E39&"|"&F39&"|"&G39&"|"&H39&"|"&I39&"|"&J39&"|"&K39&"|"&L39 | N39: =IF(COUNTIF(M$2:M39,M39)>1,1,0) | O39: =IF(AND(N39=0,COUNTIFS(B$2:B$43,B39,N$2:N$43,0,A$2:A$43,"<"&A39)>0),1,0) | P39: =IF(N39+O39=0,1,0) | Q39: =UPPER(LEFT(TRIM(C39),1)) | R39: =IF(UPPER(LEFT(TRIM(J39),1))="Y","yes",IF(UPPER(LEFT(TRIM(J39),1))="N","no","")) | S39: =IF(F39<3,F39*100,IF(OR(F39<120,F39>220),"",F39)) | T39: =IF(OR(G39<30,G39>250),"",G39) | U39: =IF(OR(H39=-99,H39<70,H39>260),"",H39) | V39: =IF(OR(I39<40,I39>150),"",I39) | W39: =IF(AND(U39<>"",V39<>""),IF(V39>=U39,1,0),0) | X39: =IF(W39=1,"",U39) | Y39: =IF(W39=1,"",V39) | Z39: =IF(Q39="M","",K39) | AA39: =IF(D39>E39,"",D39) | AB39: =IF(AA39="","",DATEDIF(AA39,E39,"y")) | AC39: =IF(AND(P39=1,OR(AB39="",AB39>=18)),1,0) | AD39: =IF(OR(S39="",T39=""),"",T39/(S39/100)^2) | AE39: =IF(AB39="","",IF(AB39<40,1,IF(AB39<60,2,3))) | AF39: =COUNTIF(labs!$A$2:$A$84,B39) | AG39: =IF(AF39=0,"",AVERAGEIF(labs!$A$2:$A$84,B39,labs!$C$2:$C$84))
A40: 39 | B40: 39 | C40: M | D40: 21677 | E40: 45726 | F40: 165 | G40: 67.4 | H40: 144 | I40: 78 | J40: y | L40: 6.4 | M40: =A40&"|"&B40&"|"&C40&"|"&D40&"|"&E40&"|"&F40&"|"&G40&"|"&H40&"|"&I40&"|"&J40&"|"&K40&"|"&L40 | N40: =IF(COUNTIF(M$2:M40,M40)>1,1,0) | O40: =IF(AND(N40=0,COUNTIFS(B$2:B$43,B40,N$2:N$43,0,A$2:A$43,"<"&A40)>0),1,0) | P40: =IF(N40+O40=0,1,0) | Q40: =UPPER(LEFT(TRIM(C40),1)) | R40: =IF(UPPER(LEFT(TRIM(J40),1))="Y","yes",IF(UPPER(LEFT(TRIM(J40),1))="N","no","")) | S40: =IF(F40<3,F40*100,IF(OR(F40<120,F40>220),"",F40)) | T40: =IF(OR(G40<30,G40>250),"",G40) | U40: =IF(OR(H40=-99,H40<70,H40>260),"",H40) | V40: =IF(OR(I40<40,I40>150),"",I40) | W40: =IF(AND(U40<>"",V40<>""),IF(V40>=U40,1,0),0) | X40: =IF(W40=1,"",U40) | Y40: =IF(W40=1,"",V40) | Z40: =IF(Q40="M","",K40) | AA40: =IF(D40>E40,"",D40) | AB40: =IF(AA40="","",DATEDIF(AA40,E40,"y")) | AC40: =IF(AND(P40=1,OR(AB40="",AB40>=18)),1,0) | AD40: =IF(OR(S40="",T40=""),"",T40/(S40/100)^2) | AE40: =IF(AB40="","",IF(AB40<40,1,IF(AB40<60,2,3))) | AF40: =COUNTIF(labs!$A$2:$A$84,B40) | AG40: =IF(AF40=0,"",AVERAGEIF(labs!$A$2:$A$84,B40,labs!$C$2:$C$84))
...

Sheet labs
A1: pid | B1: test_date | C1: ldl | D1: hdl | E1: unmatched
A2: 1 | B2: 45762 | C2: 163 | D2: 46 | E2: =IF(COUNTIFS(raw!$B$2:$B$43,A2,raw!$AC$2:$AC$43,1)=0,1,0)
A3: 1 | B3: 45886 | C3: 120 | D3: 45 | E3: =IF(COUNTIFS(raw!$B$2:$B$43,A3,raw!$AC$2:$AC$43,1)=0,1,0)
A4: 1 | B4: 45954 | C4: 128 | D4: 53 | E4: =IF(COUNTIFS(raw!$B$2:$B$43,A4,raw!$AC$2:$AC$43,1)=0,1,0)
A5: 2 | B5: 45701 | C5: 99 | D5: 46 | E5: =IF(COUNTIFS(raw!$B$2:$B$43,A5,raw!$AC$2:$AC$43,1)=0,1,0)
A6: 2 | B6: 45729 | C6: 61 | D6: 54 | E6: =IF(COUNTIFS(raw!$B$2:$B$43,A6,raw!$AC$2:$AC$43,1)=0,1,0)
A7: 2 | B7: 45850 | C7: 123 | D7: 59 | E7: =IF(COUNTIFS(raw!$B$2:$B$43,A7,raw!$AC$2:$AC$43,1)=0,1,0)
A8: 3 | B8: 45886 | C8: 208 | D8: 51 | E8: =IF(COUNTIFS(raw!$B$2:$B$43,A8,raw!$AC$2:$AC$43,1)=0,1,0)
A9: 3 | B9: 45956 | C9: 98 | D9: 40 | E9: =IF(COUNTIFS(raw!$B$2:$B$43,A9,raw!$AC$2:$AC$43,1)=0,1,0)
A10: 5 | B10: 45680 | C10: 79 | D10: 41 | E10: =IF(COUNTIFS(raw!$B$2:$B$43,A10,raw!$AC$2:$AC$43,1)=0,1,0)
A11: 5 | B11: 45742 | C11: 136 | D11: 48 | E11: =IF(COUNTIFS(raw!$B$2:$B$43,A11,raw!$AC$2:$AC$43,1)=0,1,0)
A12: 5 | B12: 45886 | C12: 162 | D12: 48 | E12: =IF(COUNTIFS(raw!$B$2:$B$43,A12,raw!$AC$2:$AC$43,1)=0,1,0)
A13: 6 | B13: 45670 | C13: 90 | D13: 26 | E13: =IF(COUNTIFS(raw!$B$2:$B$43,A13,raw!$AC$2:$AC$43,1)=0,1,0)
... A84: 99 | B84: 45809 | C84: 140 | D84: 40 | E84: =IF(COUNTIFS(raw!$B$2:$B$43,A84,raw!$AC$2:$AC$43,1)=0,1,0)

Sheet site2
A1: entry_no | B1: pid | C1: sex | D1: dob | E1: visit_date | F1: height_cm | G1: weight_kg | H1: sbp | I1: dbp | J1: smoker | K1: pregnant | L1: hba1c
A2: 101 | B2: 101 | C2: F | D2: 22354 | E2: 45749 | F2: 158 | G2: 71.5 | H2: 142 | I2: 88 | J2: no | K2: no | L2: 7.2
A3: 102 | B3: 102 | C3: M | D3: 27700 | E3: 45756 | F3: 176 | G3: 88.2 | H3: 150 | I3: 92 | J3: yes | L3: 6.5
A4: 103 | B4: 103 | C4: F | D4: 21387 | E4: 45792 | F4: 162 | G4: 64 | H4: 128 | I4: 79 | J4: no | K4: no | L4: 5.9
A5: 104 | B5: 104 | C5: M | D5: 30346 | E5: 45828 | F5: 181 | G5: 95.4 | H5: 135 | I5: 84 | J5: yes | L5: 8.1
A6: 105 | B6: 105 | C6: F | D6: 25455 | E6: 45839 | F6: 155 | G6: 77.3 | H6: 160 | I6: 96 | J6: no | K6: no | L6: 7
